<?xml version="1.0"?>
<robot name="SampleRobot">
<!-- Link Definition -->
 <link name="base_footprint" />
 <link name="base_link" />
 
 <link name="body_link">
  <visual>
   <geometry>
    <box size="0.2 0.15 0.05" />
   </geometry>
   <material name="green">
    <color rgba="0 1 0 1" />
   </material>
  </visual>
 </link>
 
 <link name="wheel_right_link">
  <visual>
   <geometry>
     <cylinder radius="0.025" length="0.03" />
   </geometry>
   <material name="green">
    <color rgba="1 0.647 0 1" />
   </material>
  </visual>
 </link>
 
 <link name="wheel_left_link">
   <visual>
   <geometry>
     <cylinder radius="0.025" length="0.03" />
   </geometry>
   <material name="green">
    <color rgba="1 0.647 0 1" />
   </material>
  </visual>
 </link>
 
 <link name="caster_front_link">
   <visual>
   <geometry>
     <sphere radius="0.025" />
   </geometry>
   <material name="green">
    <color rgba="0 0 0 1" />
   </material>
  </visual>
 </link>
 
<!-- Joint Definition -->
 <joint name="base_joint" type="fixed">
  <parent link="base_footprint"/>
  <child link="base_link"/>
  <origin xyz="0 0 0" rpy="0 0 0" />
 </joint>
 
 <joint name="body_joint" type="fixed">
  <parent link="base_link" />
  <child link="body_link" />
  <origin xyz="0 0 0" rpy="0 0 0" />
 </joint>
 
 <joint name="wheel_right_joint" type="continuous">
  <parent link="base_link" />
  <child link="wheel_right_link" />
  <origin xyz="-0.1 -0.09 -0.025" rpy="-1.57 0 0" />
  <axis xyz="0 0 1" />
 </joint>
 
 <joint name="wheel_left_joint" type="continuous">
  <parent link="base_link" />
  <child link="wheel_left_link" />
  <origin xyz="-0.1 0.09 -0.025" rpy="-1.57 0 0" />
  <axis xyz="0 0 1" />
 </joint>
 
 <joint name="caster_front_joint" type="fixed">
  <parent link="base_link" />
  <child link="caster_front_link" />
  <origin xyz="0.075 0 -0.025" rpy="0 0 0" />
 </joint>
</robot>
